[2025-02-19T02:21:17.366+0000] {local_task_job_runner.py:123} INFO - ::group::Pre task execution logs
[2025-02-19T02:21:17.416+0000] {taskinstance.py:2614} INFO - Dependencies all met for dep_context=non-requeueable deps ti=<TaskInstance: etl_pipeline_with_tasks.extract_postgres scheduled__2025-02-18T00:00:00+00:00 [queued]>
[2025-02-19T02:21:17.441+0000] {taskinstance.py:2614} INFO - Dependencies all met for dep_context=requeueable deps ti=<TaskInstance: etl_pipeline_with_tasks.extract_postgres scheduled__2025-02-18T00:00:00+00:00 [queued]>
[2025-02-19T02:21:17.443+0000] {taskinstance.py:2867} INFO - Starting attempt 2 of 2
[2025-02-19T02:21:17.482+0000] {taskinstance.py:2890} INFO - Executing <Task(_PythonDecoratedOperator): extract_postgres> on 2025-02-18 00:00:00+00:00
[2025-02-19T02:21:17.513+0000] {standard_task_runner.py:104} INFO - Running: ['***', 'tasks', 'run', 'etl_pipeline_with_tasks', 'extract_postgres', 'scheduled__2025-02-18T00:00:00+00:00', '--job-id', '36', '--raw', '--subdir', 'DAGS_FOLDER/etl_pipeline.py', '--cfg-path', '/tmp/tmpo6z9onph']
[2025-02-19T02:21:17.523+0000] {standard_task_runner.py:105} INFO - Job 36: Subtask extract_postgres
[2025-02-19T02:21:17.522+0000] {logging_mixin.py:190} WARNING - /home/***/.local/lib/python3.12/site-packages/***/task/task_runner/standard_task_runner.py:70 DeprecationWarning: This process (pid=332) is multi-threaded, use of fork() may lead to deadlocks in the child.
[2025-02-19T02:21:17.525+0000] {standard_task_runner.py:72} INFO - Started process 351 to run task
[2025-02-19T02:21:17.653+0000] {task_command.py:467} INFO - Running <TaskInstance: etl_pipeline_with_tasks.extract_postgres scheduled__2025-02-18T00:00:00+00:00 [running]> on host edea50f41cba
[2025-02-19T02:21:17.894+0000] {taskinstance.py:3134} INFO - Exporting env vars: AIRFLOW_CTX_DAG_OWNER='***' AIRFLOW_CTX_DAG_ID='etl_pipeline_with_tasks' AIRFLOW_CTX_TASK_ID='extract_postgres' AIRFLOW_CTX_EXECUTION_DATE='2025-02-18T00:00:00+00:00' AIRFLOW_CTX_TRY_NUMBER='2' AIRFLOW_CTX_DAG_RUN_ID='scheduled__2025-02-18T00:00:00+00:00'
[2025-02-19T02:21:17.899+0000] {taskinstance.py:732} INFO - ::endgroup::
[2025-02-19T02:21:17.906+0000] {extract_postgresql.py:75} INFO - Creating connection to RDS Postgresql Database
[2025-02-19T02:21:18.669+0000] {extract_postgresql.py:84} INFO - Connection established
[2025-02-19T02:21:18.672+0000] {extract_postgresql.py:99} INFO - Loading postgres data
[2025-02-19T02:21:18.710+0000] {logging_mixin.py:190} WARNING - /opt/***/src/etl/extract_postgresql.py:100 UserWarning: pandas only supports SQLAlchemy connectable (engine/connection) or database string URI or sqlite3 DBAPI2 connection. Other DBAPI2 objects are not tested. Please consider using SQLAlchemy.
[2025-02-19T02:21:20.202+0000] {extract_postgresql.py:110} INFO - Connection invalid
[2025-02-19T02:21:20.210+0000] {taskinstance.py:3313} ERROR - Task failed with exception
Traceback (most recent call last):
  File "/opt/airflow/src/etl/extract_postgresql.py", line 100, in get_dataframe_from_rds
    df = pd.read_sql_query(get_data_query, conn)
         ^^^^^^^^^^^^^^^^^^^^^^^^^^^^^^^^^^^^^^^
  File "/home/airflow/.local/lib/python3.12/site-packages/pandas/io/sql.py", line 526, in read_sql_query
    return pandas_sql.read_query(
           ^^^^^^^^^^^^^^^^^^^^^^
  File "/home/airflow/.local/lib/python3.12/site-packages/pandas/io/sql.py", line 2756, in read_query
    frame = _wrap_result(
            ^^^^^^^^^^^^^
  File "/home/airflow/.local/lib/python3.12/site-packages/pandas/io/sql.py", line 204, in _wrap_result
    frame = _convert_arrays_to_dataframe(data, columns, coerce_float, dtype_backend)
            ^^^^^^^^^^^^^^^^^^^^^^^^^^^^^^^^^^^^^^^^^^^^^^^^^^^^^^^^^^^^^^^^^^^^^^^^
  File "/home/airflow/.local/lib/python3.12/site-packages/pandas/io/sql.py", line 167, in _convert_arrays_to_dataframe
    arrays = convert_object_array(
             ^^^^^^^^^^^^^^^^^^^^^
  File "/home/airflow/.local/lib/python3.12/site-packages/pandas/core/internals/construction.py", line 1070, in convert_object_array
    arrays = [convert(arr) for arr in content]
              ^^^^^^^^^^^^
  File "/home/airflow/.local/lib/python3.12/site-packages/pandas/core/internals/construction.py", line 1030, in convert
    arr = lib.maybe_convert_objects(
          ^^^^^^^^^^^^^^^^^^^^^^^^^^
  File "lib.pyx", line 2538, in pandas._libs.lib.maybe_convert_objects
TypeError: Cannot convert numpy.ndarray to numpy.ndarray

During handling of the above exception, another exception occurred:

Traceback (most recent call last):
  File "/home/airflow/.local/lib/python3.12/site-packages/airflow/models/taskinstance.py", line 768, in _execute_task
    result = _execute_callable(context=context, **execute_callable_kwargs)
             ^^^^^^^^^^^^^^^^^^^^^^^^^^^^^^^^^^^^^^^^^^^^^^^^^^^^^^^^^^^^^
  File "/home/airflow/.local/lib/python3.12/site-packages/airflow/models/taskinstance.py", line 734, in _execute_callable
    return ExecutionCallableRunner(
           ^^^^^^^^^^^^^^^^^^^^^^^^
  File "/home/airflow/.local/lib/python3.12/site-packages/airflow/utils/operator_helpers.py", line 252, in run
    return self.func(*args, **kwargs)
           ^^^^^^^^^^^^^^^^^^^^^^^^^^
  File "/home/airflow/.local/lib/python3.12/site-packages/airflow/models/baseoperator.py", line 424, in wrapper
    return func(self, *args, **kwargs)
           ^^^^^^^^^^^^^^^^^^^^^^^^^^^
  File "/home/airflow/.local/lib/python3.12/site-packages/airflow/decorators/base.py", line 266, in execute
    return_value = super().execute(context)
                   ^^^^^^^^^^^^^^^^^^^^^^^^
  File "/home/airflow/.local/lib/python3.12/site-packages/airflow/models/baseoperator.py", line 424, in wrapper
    return func(self, *args, **kwargs)
           ^^^^^^^^^^^^^^^^^^^^^^^^^^^
  File "/home/airflow/.local/lib/python3.12/site-packages/airflow/operators/python.py", line 238, in execute
    return_value = self.execute_callable()
                   ^^^^^^^^^^^^^^^^^^^^^^^
  File "/home/airflow/.local/lib/python3.12/site-packages/airflow/operators/python.py", line 256, in execute_callable
    return runner.run(*self.op_args, **self.op_kwargs)
           ^^^^^^^^^^^^^^^^^^^^^^^^^^^^^^^^^^^^^^^^^^^
  File "/home/airflow/.local/lib/python3.12/site-packages/airflow/utils/operator_helpers.py", line 252, in run
    return self.func(*args, **kwargs)
           ^^^^^^^^^^^^^^^^^^^^^^^^^^
  File "/opt/airflow/dags/etl_pipeline.py", line 58, in extract_postgres
    postgres_df = get_validated_postgres_data()
                  ^^^^^^^^^^^^^^^^^^^^^^^^^^^^^
  File "/opt/airflow/src/etl/extract_postgresql.py", line 116, in get_validated_postgres_data
    df = get_dataframe_from_rds()
         ^^^^^^^^^^^^^^^^^^^^^^^^
  File "/opt/airflow/src/etl/extract_postgresql.py", line 111, in get_dataframe_from_rds
    raise CustomException(e, sys)
src.utils.exception.CustomException: Error occurred in python script name /opt/airflow/src/etl/extract_postgresql.py line number 100 error message Cannot convert numpy.ndarray to numpy.ndarray
[2025-02-19T02:21:20.295+0000] {taskinstance.py:1226} INFO - Marking task as FAILED. dag_id=etl_pipeline_with_tasks, task_id=extract_postgres, run_id=scheduled__2025-02-18T00:00:00+00:00, execution_date=20250218T000000, start_date=20250219T022117, end_date=20250219T022120
[2025-02-19T02:21:20.364+0000] {taskinstance.py:341} INFO - ::group::Post task execution logs
[2025-02-19T02:21:20.365+0000] {standard_task_runner.py:124} ERROR - Failed to execute job 36 for task extract_postgres (Error occurred in python script name /opt/airflow/src/etl/extract_postgresql.py line number 100 error message Cannot convert numpy.ndarray to numpy.ndarray; 351)
Traceback (most recent call last):
  File "/opt/airflow/src/etl/extract_postgresql.py", line 100, in get_dataframe_from_rds
    df = pd.read_sql_query(get_data_query, conn)
         ^^^^^^^^^^^^^^^^^^^^^^^^^^^^^^^^^^^^^^^
  File "/home/airflow/.local/lib/python3.12/site-packages/pandas/io/sql.py", line 526, in read_sql_query
    return pandas_sql.read_query(
           ^^^^^^^^^^^^^^^^^^^^^^
  File "/home/airflow/.local/lib/python3.12/site-packages/pandas/io/sql.py", line 2756, in read_query
    frame = _wrap_result(
            ^^^^^^^^^^^^^
  File "/home/airflow/.local/lib/python3.12/site-packages/pandas/io/sql.py", line 204, in _wrap_result
    frame = _convert_arrays_to_dataframe(data, columns, coerce_float, dtype_backend)
            ^^^^^^^^^^^^^^^^^^^^^^^^^^^^^^^^^^^^^^^^^^^^^^^^^^^^^^^^^^^^^^^^^^^^^^^^
  File "/home/airflow/.local/lib/python3.12/site-packages/pandas/io/sql.py", line 167, in _convert_arrays_to_dataframe
    arrays = convert_object_array(
             ^^^^^^^^^^^^^^^^^^^^^
  File "/home/airflow/.local/lib/python3.12/site-packages/pandas/core/internals/construction.py", line 1070, in convert_object_array
    arrays = [convert(arr) for arr in content]
              ^^^^^^^^^^^^
  File "/home/airflow/.local/lib/python3.12/site-packages/pandas/core/internals/construction.py", line 1030, in convert
    arr = lib.maybe_convert_objects(
          ^^^^^^^^^^^^^^^^^^^^^^^^^^
  File "lib.pyx", line 2538, in pandas._libs.lib.maybe_convert_objects
TypeError: Cannot convert numpy.ndarray to numpy.ndarray

During handling of the above exception, another exception occurred:

Traceback (most recent call last):
  File "/home/airflow/.local/lib/python3.12/site-packages/airflow/task/task_runner/standard_task_runner.py", line 117, in _start_by_fork
    ret = args.func(args, dag=self.dag)
          ^^^^^^^^^^^^^^^^^^^^^^^^^^^^^
  File "/home/airflow/.local/lib/python3.12/site-packages/airflow/cli/cli_config.py", line 49, in command
    return func(*args, **kwargs)
           ^^^^^^^^^^^^^^^^^^^^^
  File "/home/airflow/.local/lib/python3.12/site-packages/airflow/utils/cli.py", line 116, in wrapper
    return f(*args, **kwargs)
           ^^^^^^^^^^^^^^^^^^
  File "/home/airflow/.local/lib/python3.12/site-packages/airflow/cli/commands/task_command.py", line 483, in task_run
    task_return_code = _run_task_by_selected_method(args, _dag, ti)
                       ^^^^^^^^^^^^^^^^^^^^^^^^^^^^^^^^^^^^^^^^^^^^
  File "/home/airflow/.local/lib/python3.12/site-packages/airflow/cli/commands/task_command.py", line 256, in _run_task_by_selected_method
    return _run_raw_task(args, ti)
           ^^^^^^^^^^^^^^^^^^^^^^^
  File "/home/airflow/.local/lib/python3.12/site-packages/airflow/cli/commands/task_command.py", line 341, in _run_raw_task
    return ti._run_raw_task(
           ^^^^^^^^^^^^^^^^^
  File "/home/airflow/.local/lib/python3.12/site-packages/airflow/utils/session.py", line 97, in wrapper
    return func(*args, session=session, **kwargs)
           ^^^^^^^^^^^^^^^^^^^^^^^^^^^^^^^^^^^^^^
  File "/home/airflow/.local/lib/python3.12/site-packages/airflow/models/taskinstance.py", line 3006, in _run_raw_task
    return _run_raw_task(
           ^^^^^^^^^^^^^^
  File "/home/airflow/.local/lib/python3.12/site-packages/airflow/models/taskinstance.py", line 274, in _run_raw_task
    TaskInstance._execute_task_with_callbacks(
  File "/home/airflow/.local/lib/python3.12/site-packages/airflow/models/taskinstance.py", line 3161, in _execute_task_with_callbacks
    result = self._execute_task(context, task_orig)
             ^^^^^^^^^^^^^^^^^^^^^^^^^^^^^^^^^^^^^^
  File "/home/airflow/.local/lib/python3.12/site-packages/airflow/models/taskinstance.py", line 3185, in _execute_task
    return _execute_task(self, context, task_orig)
           ^^^^^^^^^^^^^^^^^^^^^^^^^^^^^^^^^^^^^^^
  File "/home/airflow/.local/lib/python3.12/site-packages/airflow/models/taskinstance.py", line 768, in _execute_task
    result = _execute_callable(context=context, **execute_callable_kwargs)
             ^^^^^^^^^^^^^^^^^^^^^^^^^^^^^^^^^^^^^^^^^^^^^^^^^^^^^^^^^^^^^
  File "/home/airflow/.local/lib/python3.12/site-packages/airflow/models/taskinstance.py", line 734, in _execute_callable
    return ExecutionCallableRunner(
           ^^^^^^^^^^^^^^^^^^^^^^^^
  File "/home/airflow/.local/lib/python3.12/site-packages/airflow/utils/operator_helpers.py", line 252, in run
    return self.func(*args, **kwargs)
           ^^^^^^^^^^^^^^^^^^^^^^^^^^
  File "/home/airflow/.local/lib/python3.12/site-packages/airflow/models/baseoperator.py", line 424, in wrapper
    return func(self, *args, **kwargs)
           ^^^^^^^^^^^^^^^^^^^^^^^^^^^
  File "/home/airflow/.local/lib/python3.12/site-packages/airflow/decorators/base.py", line 266, in execute
    return_value = super().execute(context)
                   ^^^^^^^^^^^^^^^^^^^^^^^^
  File "/home/airflow/.local/lib/python3.12/site-packages/airflow/models/baseoperator.py", line 424, in wrapper
    return func(self, *args, **kwargs)
           ^^^^^^^^^^^^^^^^^^^^^^^^^^^
  File "/home/airflow/.local/lib/python3.12/site-packages/airflow/operators/python.py", line 238, in execute
    return_value = self.execute_callable()
                   ^^^^^^^^^^^^^^^^^^^^^^^
  File "/home/airflow/.local/lib/python3.12/site-packages/airflow/operators/python.py", line 256, in execute_callable
    return runner.run(*self.op_args, **self.op_kwargs)
           ^^^^^^^^^^^^^^^^^^^^^^^^^^^^^^^^^^^^^^^^^^^
  File "/home/airflow/.local/lib/python3.12/site-packages/airflow/utils/operator_helpers.py", line 252, in run
    return self.func(*args, **kwargs)
           ^^^^^^^^^^^^^^^^^^^^^^^^^^
  File "/opt/airflow/dags/etl_pipeline.py", line 58, in extract_postgres
    postgres_df = get_validated_postgres_data()
                  ^^^^^^^^^^^^^^^^^^^^^^^^^^^^^
  File "/opt/airflow/src/etl/extract_postgresql.py", line 116, in get_validated_postgres_data
    df = get_dataframe_from_rds()
         ^^^^^^^^^^^^^^^^^^^^^^^^
  File "/opt/airflow/src/etl/extract_postgresql.py", line 111, in get_dataframe_from_rds
    raise CustomException(e, sys)
src.utils.exception.CustomException: Error occurred in python script name /opt/airflow/src/etl/extract_postgresql.py line number 100 error message Cannot convert numpy.ndarray to numpy.ndarray
[2025-02-19T02:21:20.420+0000] {local_task_job_runner.py:266} INFO - Task exited with return code 1
[2025-02-19T02:21:20.475+0000] {taskinstance.py:3901} INFO - 0 downstream tasks scheduled from follow-on schedule check
[2025-02-19T02:21:20.485+0000] {local_task_job_runner.py:245} INFO - ::endgroup::
