[2025-02-20T09:23:30.249+0000] {local_task_job_runner.py:123} INFO - ::group::Pre task execution logs
[2025-02-20T09:23:30.274+0000] {taskinstance.py:2614} INFO - Dependencies all met for dep_context=non-requeueable deps ti=<TaskInstance: etl_pipeline_with_tasks.extract_postgres manual__2025-02-20T09:23:28.163462+00:00 [queued]>
[2025-02-20T09:23:30.290+0000] {taskinstance.py:2614} INFO - Dependencies all met for dep_context=requeueable deps ti=<TaskInstance: etl_pipeline_with_tasks.extract_postgres manual__2025-02-20T09:23:28.163462+00:00 [queued]>
[2025-02-20T09:23:30.292+0000] {taskinstance.py:2867} INFO - Starting attempt 1 of 2
[2025-02-20T09:23:30.319+0000] {taskinstance.py:2890} INFO - Executing <Task(_PythonDecoratedOperator): extract_postgres> on 2025-02-20 09:23:28.163462+00:00
[2025-02-20T09:23:30.328+0000] {standard_task_runner.py:72} INFO - Started process 828 to run task
[2025-02-20T09:23:30.336+0000] {standard_task_runner.py:104} INFO - Running: ['***', 'tasks', 'run', 'etl_pipeline_with_tasks', 'extract_postgres', 'manual__2025-02-20T09:23:28.163462+00:00', '--job-id', '60', '--raw', '--subdir', 'DAGS_FOLDER/etl_pipeline.py', '--cfg-path', '/tmp/tmpy38nk972']
[2025-02-20T09:23:30.342+0000] {standard_task_runner.py:105} INFO - Job 60: Subtask extract_postgres
[2025-02-20T09:23:30.428+0000] {task_command.py:467} INFO - Running <TaskInstance: etl_pipeline_with_tasks.extract_postgres manual__2025-02-20T09:23:28.163462+00:00 [running]> on host edca0d367328
[2025-02-20T09:23:30.569+0000] {taskinstance.py:3134} INFO - Exporting env vars: AIRFLOW_CTX_DAG_OWNER='***' AIRFLOW_CTX_DAG_ID='etl_pipeline_with_tasks' AIRFLOW_CTX_TASK_ID='extract_postgres' AIRFLOW_CTX_EXECUTION_DATE='2025-02-20T09:23:28.163462+00:00' AIRFLOW_CTX_TRY_NUMBER='1' AIRFLOW_CTX_DAG_RUN_ID='manual__2025-02-20T09:23:28.163462+00:00'
[2025-02-20T09:23:30.572+0000] {taskinstance.py:732} INFO - ::endgroup::
[2025-02-20T09:23:30.577+0000] {extract_postgresql.py:75} INFO - Creating connection to RDS Postgresql Database
[2025-02-20T09:23:30.589+0000] {extract_postgresql.py:87} INFO - Error connecting to PostgresQL: could not translate host name "aws-0-ap-southeast-1.pooler.supabase.com" to address: Name or service not known

[2025-02-20T09:23:30.590+0000] {taskinstance.py:3313} ERROR - Task failed with exception
Traceback (most recent call last):
  File "/opt/airflow/src/etl/extract_postgresql.py", line 76, in get_postgres_connection
    conn = psycopg2.connect(
  File "/home/airflow/.local/lib/python3.9/site-packages/psycopg2/__init__.py", line 122, in connect
    conn = _connect(dsn, connection_factory=connection_factory, **kwasync)
psycopg2.OperationalError: could not translate host name "aws-0-ap-southeast-1.pooler.supabase.com" to address: Name or service not known


During handling of the above exception, another exception occurred:

Traceback (most recent call last):
  File "/home/airflow/.local/lib/python3.9/site-packages/airflow/models/taskinstance.py", line 768, in _execute_task
    result = _execute_callable(context=context, **execute_callable_kwargs)
  File "/home/airflow/.local/lib/python3.9/site-packages/airflow/models/taskinstance.py", line 734, in _execute_callable
    return ExecutionCallableRunner(
  File "/home/airflow/.local/lib/python3.9/site-packages/airflow/utils/operator_helpers.py", line 252, in run
    return self.func(*args, **kwargs)
  File "/home/airflow/.local/lib/python3.9/site-packages/airflow/models/baseoperator.py", line 424, in wrapper
    return func(self, *args, **kwargs)
  File "/home/airflow/.local/lib/python3.9/site-packages/airflow/decorators/base.py", line 266, in execute
    return_value = super().execute(context)
  File "/home/airflow/.local/lib/python3.9/site-packages/airflow/models/baseoperator.py", line 424, in wrapper
    return func(self, *args, **kwargs)
  File "/home/airflow/.local/lib/python3.9/site-packages/airflow/operators/python.py", line 238, in execute
    return_value = self.execute_callable()
  File "/home/airflow/.local/lib/python3.9/site-packages/airflow/operators/python.py", line 256, in execute_callable
    return runner.run(*self.op_args, **self.op_kwargs)
  File "/home/airflow/.local/lib/python3.9/site-packages/airflow/utils/operator_helpers.py", line 252, in run
    return self.func(*args, **kwargs)
  File "/opt/airflow/dags/etl_pipeline.py", line 58, in extract_postgres
    postgres_df = get_validated_postgres_data()
  File "/opt/airflow/src/etl/extract_postgresql.py", line 116, in get_validated_postgres_data
    df = get_dataframe_from_rds()
  File "/opt/airflow/src/etl/extract_postgresql.py", line 92, in get_dataframe_from_rds
    conn = get_postgres_connection()
  File "/opt/airflow/src/etl/extract_postgresql.py", line 88, in get_postgres_connection
    raise CustomException(e, sys)
src.utils.exception.CustomException: Error occurred in python script name /opt/airflow/src/etl/extract_postgresql.py line number 76 error message could not translate host name "aws-0-ap-southeast-1.pooler.supabase.com" to address: Name or service not known

[2025-02-20T09:23:30.621+0000] {taskinstance.py:1226} INFO - Marking task as UP_FOR_RETRY. dag_id=etl_pipeline_with_tasks, task_id=extract_postgres, run_id=manual__2025-02-20T09:23:28.163462+00:00, execution_date=20250220T092328, start_date=20250220T092330, end_date=20250220T092330
[2025-02-20T09:23:30.669+0000] {taskinstance.py:341} INFO - ::group::Post task execution logs
[2025-02-20T09:23:30.670+0000] {standard_task_runner.py:124} ERROR - Failed to execute job 60 for task extract_postgres (Error occurred in python script name /opt/airflow/src/etl/extract_postgresql.py line number 76 error message could not translate host name "aws-0-ap-southeast-1.pooler.supabase.com" to address: Name or service not known
; 828)
Traceback (most recent call last):
  File "/opt/airflow/src/etl/extract_postgresql.py", line 76, in get_postgres_connection
    conn = psycopg2.connect(
  File "/home/airflow/.local/lib/python3.9/site-packages/psycopg2/__init__.py", line 122, in connect
    conn = _connect(dsn, connection_factory=connection_factory, **kwasync)
psycopg2.OperationalError: could not translate host name "aws-0-ap-southeast-1.pooler.supabase.com" to address: Name or service not known


During handling of the above exception, another exception occurred:

Traceback (most recent call last):
  File "/home/airflow/.local/lib/python3.9/site-packages/airflow/task/task_runner/standard_task_runner.py", line 117, in _start_by_fork
    ret = args.func(args, dag=self.dag)
  File "/home/airflow/.local/lib/python3.9/site-packages/airflow/cli/cli_config.py", line 49, in command
    return func(*args, **kwargs)
  File "/home/airflow/.local/lib/python3.9/site-packages/airflow/utils/cli.py", line 116, in wrapper
    return f(*args, **kwargs)
  File "/home/airflow/.local/lib/python3.9/site-packages/airflow/cli/commands/task_command.py", line 483, in task_run
    task_return_code = _run_task_by_selected_method(args, _dag, ti)
  File "/home/airflow/.local/lib/python3.9/site-packages/airflow/cli/commands/task_command.py", line 256, in _run_task_by_selected_method
    return _run_raw_task(args, ti)
  File "/home/airflow/.local/lib/python3.9/site-packages/airflow/cli/commands/task_command.py", line 341, in _run_raw_task
    return ti._run_raw_task(
  File "/home/airflow/.local/lib/python3.9/site-packages/airflow/utils/session.py", line 97, in wrapper
    return func(*args, session=session, **kwargs)
  File "/home/airflow/.local/lib/python3.9/site-packages/airflow/models/taskinstance.py", line 3006, in _run_raw_task
    return _run_raw_task(
  File "/home/airflow/.local/lib/python3.9/site-packages/airflow/models/taskinstance.py", line 274, in _run_raw_task
    TaskInstance._execute_task_with_callbacks(
  File "/home/airflow/.local/lib/python3.9/site-packages/airflow/models/taskinstance.py", line 3161, in _execute_task_with_callbacks
    result = self._execute_task(context, task_orig)
  File "/home/airflow/.local/lib/python3.9/site-packages/airflow/models/taskinstance.py", line 3185, in _execute_task
    return _execute_task(self, context, task_orig)
  File "/home/airflow/.local/lib/python3.9/site-packages/airflow/models/taskinstance.py", line 768, in _execute_task
    result = _execute_callable(context=context, **execute_callable_kwargs)
  File "/home/airflow/.local/lib/python3.9/site-packages/airflow/models/taskinstance.py", line 734, in _execute_callable
    return ExecutionCallableRunner(
  File "/home/airflow/.local/lib/python3.9/site-packages/airflow/utils/operator_helpers.py", line 252, in run
    return self.func(*args, **kwargs)
  File "/home/airflow/.local/lib/python3.9/site-packages/airflow/models/baseoperator.py", line 424, in wrapper
    return func(self, *args, **kwargs)
  File "/home/airflow/.local/lib/python3.9/site-packages/airflow/decorators/base.py", line 266, in execute
    return_value = super().execute(context)
  File "/home/airflow/.local/lib/python3.9/site-packages/airflow/models/baseoperator.py", line 424, in wrapper
    return func(self, *args, **kwargs)
  File "/home/airflow/.local/lib/python3.9/site-packages/airflow/operators/python.py", line 238, in execute
    return_value = self.execute_callable()
  File "/home/airflow/.local/lib/python3.9/site-packages/airflow/operators/python.py", line 256, in execute_callable
    return runner.run(*self.op_args, **self.op_kwargs)
  File "/home/airflow/.local/lib/python3.9/site-packages/airflow/utils/operator_helpers.py", line 252, in run
    return self.func(*args, **kwargs)
  File "/opt/airflow/dags/etl_pipeline.py", line 58, in extract_postgres
    postgres_df = get_validated_postgres_data()
  File "/opt/airflow/src/etl/extract_postgresql.py", line 116, in get_validated_postgres_data
    df = get_dataframe_from_rds()
  File "/opt/airflow/src/etl/extract_postgresql.py", line 92, in get_dataframe_from_rds
    conn = get_postgres_connection()
  File "/opt/airflow/src/etl/extract_postgresql.py", line 88, in get_postgres_connection
    raise CustomException(e, sys)
src.utils.exception.CustomException: Error occurred in python script name /opt/airflow/src/etl/extract_postgresql.py line number 76 error message could not translate host name "aws-0-ap-southeast-1.pooler.supabase.com" to address: Name or service not known

[2025-02-20T09:23:30.711+0000] {local_task_job_runner.py:266} INFO - Task exited with return code 1
[2025-02-20T09:23:30.746+0000] {taskinstance.py:3901} INFO - 0 downstream tasks scheduled from follow-on schedule check
[2025-02-20T09:23:30.750+0000] {local_task_job_runner.py:245} INFO - ::endgroup::
