[2025-02-20T06:00:17.955+0000] {local_task_job_runner.py:123} INFO - ::group::Pre task execution logs
[2025-02-20T06:00:17.981+0000] {taskinstance.py:2614} INFO - Dependencies all met for dep_context=non-requeueable deps ti=<TaskInstance: etl_pipeline_with_tasks.load_to_s3 manual__2025-02-20T05:55:00.619124+00:00 [queued]>
[2025-02-20T06:00:17.994+0000] {taskinstance.py:2614} INFO - Dependencies all met for dep_context=requeueable deps ti=<TaskInstance: etl_pipeline_with_tasks.load_to_s3 manual__2025-02-20T05:55:00.619124+00:00 [queued]>
[2025-02-20T06:00:17.995+0000] {taskinstance.py:2867} INFO - Starting attempt 2 of 2
[2025-02-20T06:00:18.021+0000] {taskinstance.py:2890} INFO - Executing <Task(_PythonDecoratedOperator): load_to_s3> on 2025-02-20 05:55:00.619124+00:00
[2025-02-20T06:00:18.027+0000] {standard_task_runner.py:72} INFO - Started process 358 to run task
[2025-02-20T06:00:18.034+0000] {standard_task_runner.py:104} INFO - Running: ['***', 'tasks', 'run', 'etl_pipeline_with_tasks', 'load_to_s3', 'manual__2025-02-20T05:55:00.619124+00:00', '--job-id', '50', '--raw', '--subdir', 'DAGS_FOLDER/etl_pipeline.py', '--cfg-path', '/tmp/tmp_ybpmmka']
[2025-02-20T06:00:18.039+0000] {standard_task_runner.py:105} INFO - Job 50: Subtask load_to_s3
[2025-02-20T06:00:18.109+0000] {task_command.py:467} INFO - Running <TaskInstance: etl_pipeline_with_tasks.load_to_s3 manual__2025-02-20T05:55:00.619124+00:00 [running]> on host 2d14f8965da4
[2025-02-20T06:00:18.446+0000] {taskinstance.py:3134} INFO - Exporting env vars: AIRFLOW_CTX_DAG_OWNER='***' AIRFLOW_CTX_DAG_ID='etl_pipeline_with_tasks' AIRFLOW_CTX_TASK_ID='load_to_s3' AIRFLOW_CTX_EXECUTION_DATE='2025-02-20T05:55:00.619124+00:00' AIRFLOW_CTX_TRY_NUMBER='2' AIRFLOW_CTX_DAG_RUN_ID='manual__2025-02-20T05:55:00.619124+00:00'
[2025-02-20T06:00:18.449+0000] {taskinstance.py:732} INFO - ::endgroup::
[2025-02-20T06:00:18.480+0000] {logging_mixin.py:190} WARNING - /opt/***/dags/etl_pipeline.py:82 FutureWarning: Passing literal json to 'read_json' is deprecated and will be removed in a future version. To read from a literal string, wrap it in a 'StringIO' object.
[2025-02-20T06:00:20.931+0000] {taskinstance.py:3313} ERROR - Task failed with exception
Traceback (most recent call last):
  File "/opt/airflow/src/etl/load_s3.py", line 35, in upload_dataframe_to_s3
    s3_client.put_object(Bucket=bucket_name, Key=s3_key, Body=csv_buffer.getvalue())
  File "/home/airflow/.local/lib/python3.9/site-packages/botocore/client.py", line 569, in _api_call
    return self._make_api_call(operation_name, kwargs)
  File "/home/airflow/.local/lib/python3.9/site-packages/botocore/client.py", line 1023, in _make_api_call
    raise error_class(parsed_response, operation_name)
botocore.exceptions.ClientError: An error occurred (InvalidAccessKeyId) when calling the PutObject operation: The AWS Access Key Id you provided does not exist in our records.

During handling of the above exception, another exception occurred:

Traceback (most recent call last):
  File "/home/airflow/.local/lib/python3.9/site-packages/airflow/models/taskinstance.py", line 768, in _execute_task
    result = _execute_callable(context=context, **execute_callable_kwargs)
  File "/home/airflow/.local/lib/python3.9/site-packages/airflow/models/taskinstance.py", line 734, in _execute_callable
    return ExecutionCallableRunner(
  File "/home/airflow/.local/lib/python3.9/site-packages/airflow/utils/operator_helpers.py", line 252, in run
    return self.func(*args, **kwargs)
  File "/home/airflow/.local/lib/python3.9/site-packages/airflow/models/baseoperator.py", line 424, in wrapper
    return func(self, *args, **kwargs)
  File "/home/airflow/.local/lib/python3.9/site-packages/airflow/decorators/base.py", line 266, in execute
    return_value = super().execute(context)
  File "/home/airflow/.local/lib/python3.9/site-packages/airflow/models/baseoperator.py", line 424, in wrapper
    return func(self, *args, **kwargs)
  File "/home/airflow/.local/lib/python3.9/site-packages/airflow/operators/python.py", line 238, in execute
    return_value = self.execute_callable()
  File "/home/airflow/.local/lib/python3.9/site-packages/airflow/operators/python.py", line 256, in execute_callable
    return runner.run(*self.op_args, **self.op_kwargs)
  File "/home/airflow/.local/lib/python3.9/site-packages/airflow/utils/operator_helpers.py", line 252, in run
    return self.func(*args, **kwargs)
  File "/opt/airflow/dags/etl_pipeline.py", line 83, in load_to_s3
    upload_dataframe_to_s3(final_df, bucket_name, s3_key)
  File "/opt/airflow/src/etl/load_s3.py", line 39, in upload_dataframe_to_s3
    raise CustomException(e, sys)
src.utils.exception.CustomException: Error occurred in python script name /opt/airflow/src/etl/load_s3.py line number 35 error message An error occurred (InvalidAccessKeyId) when calling the PutObject operation: The AWS Access Key Id you provided does not exist in our records.
[2025-02-20T06:00:20.962+0000] {taskinstance.py:1226} INFO - Marking task as FAILED. dag_id=etl_pipeline_with_tasks, task_id=load_to_s3, run_id=manual__2025-02-20T05:55:00.619124+00:00, execution_date=20250220T055500, start_date=20250220T060017, end_date=20250220T060020
[2025-02-20T06:00:21.012+0000] {taskinstance.py:341} INFO - ::group::Post task execution logs
[2025-02-20T06:00:21.014+0000] {standard_task_runner.py:124} ERROR - Failed to execute job 50 for task load_to_s3 (Error occurred in python script name /opt/airflow/src/etl/load_s3.py line number 35 error message An error occurred (InvalidAccessKeyId) when calling the PutObject operation: The AWS Access Key Id you provided does not exist in our records.; 358)
Traceback (most recent call last):
  File "/opt/airflow/src/etl/load_s3.py", line 35, in upload_dataframe_to_s3
    s3_client.put_object(Bucket=bucket_name, Key=s3_key, Body=csv_buffer.getvalue())
  File "/home/airflow/.local/lib/python3.9/site-packages/botocore/client.py", line 569, in _api_call
    return self._make_api_call(operation_name, kwargs)
  File "/home/airflow/.local/lib/python3.9/site-packages/botocore/client.py", line 1023, in _make_api_call
    raise error_class(parsed_response, operation_name)
botocore.exceptions.ClientError: An error occurred (InvalidAccessKeyId) when calling the PutObject operation: The AWS Access Key Id you provided does not exist in our records.

During handling of the above exception, another exception occurred:

Traceback (most recent call last):
  File "/home/airflow/.local/lib/python3.9/site-packages/airflow/task/task_runner/standard_task_runner.py", line 117, in _start_by_fork
    ret = args.func(args, dag=self.dag)
  File "/home/airflow/.local/lib/python3.9/site-packages/airflow/cli/cli_config.py", line 49, in command
    return func(*args, **kwargs)
  File "/home/airflow/.local/lib/python3.9/site-packages/airflow/utils/cli.py", line 116, in wrapper
    return f(*args, **kwargs)
  File "/home/airflow/.local/lib/python3.9/site-packages/airflow/cli/commands/task_command.py", line 483, in task_run
    task_return_code = _run_task_by_selected_method(args, _dag, ti)
  File "/home/airflow/.local/lib/python3.9/site-packages/airflow/cli/commands/task_command.py", line 256, in _run_task_by_selected_method
    return _run_raw_task(args, ti)
  File "/home/airflow/.local/lib/python3.9/site-packages/airflow/cli/commands/task_command.py", line 341, in _run_raw_task
    return ti._run_raw_task(
  File "/home/airflow/.local/lib/python3.9/site-packages/airflow/utils/session.py", line 97, in wrapper
    return func(*args, session=session, **kwargs)
  File "/home/airflow/.local/lib/python3.9/site-packages/airflow/models/taskinstance.py", line 3006, in _run_raw_task
    return _run_raw_task(
  File "/home/airflow/.local/lib/python3.9/site-packages/airflow/models/taskinstance.py", line 274, in _run_raw_task
    TaskInstance._execute_task_with_callbacks(
  File "/home/airflow/.local/lib/python3.9/site-packages/airflow/models/taskinstance.py", line 3161, in _execute_task_with_callbacks
    result = self._execute_task(context, task_orig)
  File "/home/airflow/.local/lib/python3.9/site-packages/airflow/models/taskinstance.py", line 3185, in _execute_task
    return _execute_task(self, context, task_orig)
  File "/home/airflow/.local/lib/python3.9/site-packages/airflow/models/taskinstance.py", line 768, in _execute_task
    result = _execute_callable(context=context, **execute_callable_kwargs)
  File "/home/airflow/.local/lib/python3.9/site-packages/airflow/models/taskinstance.py", line 734, in _execute_callable
    return ExecutionCallableRunner(
  File "/home/airflow/.local/lib/python3.9/site-packages/airflow/utils/operator_helpers.py", line 252, in run
    return self.func(*args, **kwargs)
  File "/home/airflow/.local/lib/python3.9/site-packages/airflow/models/baseoperator.py", line 424, in wrapper
    return func(self, *args, **kwargs)
  File "/home/airflow/.local/lib/python3.9/site-packages/airflow/decorators/base.py", line 266, in execute
    return_value = super().execute(context)
  File "/home/airflow/.local/lib/python3.9/site-packages/airflow/models/baseoperator.py", line 424, in wrapper
    return func(self, *args, **kwargs)
  File "/home/airflow/.local/lib/python3.9/site-packages/airflow/operators/python.py", line 238, in execute
    return_value = self.execute_callable()
  File "/home/airflow/.local/lib/python3.9/site-packages/airflow/operators/python.py", line 256, in execute_callable
    return runner.run(*self.op_args, **self.op_kwargs)
  File "/home/airflow/.local/lib/python3.9/site-packages/airflow/utils/operator_helpers.py", line 252, in run
    return self.func(*args, **kwargs)
  File "/opt/airflow/dags/etl_pipeline.py", line 83, in load_to_s3
    upload_dataframe_to_s3(final_df, bucket_name, s3_key)
  File "/opt/airflow/src/etl/load_s3.py", line 39, in upload_dataframe_to_s3
    raise CustomException(e, sys)
src.utils.exception.CustomException: Error occurred in python script name /opt/airflow/src/etl/load_s3.py line number 35 error message An error occurred (InvalidAccessKeyId) when calling the PutObject operation: The AWS Access Key Id you provided does not exist in our records.
[2025-02-20T06:00:21.059+0000] {local_task_job_runner.py:266} INFO - Task exited with return code 1
[2025-02-20T06:00:21.088+0000] {taskinstance.py:3901} INFO - 0 downstream tasks scheduled from follow-on schedule check
[2025-02-20T06:00:21.092+0000] {local_task_job_runner.py:245} INFO - ::endgroup::
